Workbook
Name CAR_CourseFileStatus: Lists!$K$2:$K$4
Name CourseOutlineStatus: Lists!$A$2:$A$4
Name CTStatus: Lists!$C$2:$C$6
Name ExaminerStatus: Lists!$G$2:$G$4
Name Faculty_List: Lists!$B$2:$B$15
Name FeedbackStatus: Lists!$D$2:$D$3
Name GradesheetPrepStatus: Lists!$I$2:$I$5
Name GradesheetScrutinyStatus: Lists!$J$2:$J$5
Name QMStatus: Lists!$F$2:$F$4
Name QPStatus: Lists!$E$2:$E$4
Name ScriptScrutinyStatus: Lists!$H$2:$H$4
Name SessionalEvaluations: Lists!$L$2:$L$22
Name SessionalEvaluationStatus: Lists!$M$2:$M$5

Sheet Instructions
A1: Academic Term Activity Tracker Instructions
A2: This workbook is intended to track course outlines, class tests, and the full question-setting / moderation / examination / grading workflow for every course in a term. It is designed for the Course Coordinator / BUGS / Department Head to review status at a glance.
A4: How to use this file
A5: 1. Course List sheet | B5: Enter every course offered this term, its section(s), credit hours and the assigned course teacher(s) with contact details.
A6: 2. Progress Tracker sheet | B6: Pick a Course Code from the dropdown in column A (it must already exist in 'Course List'); Course Title, Section and Teacher will fill in automatically. Then update Course Outline, Class Test (CT1-CT4), and the full exam workflow (question preparation -> moderation -> examination -> script scrutiny -> gradesheet preparation -> gradesheet scrutiny) columns as work progresses.
A7: 3. Status dropdowns | B7: Every status column is a dropdown. Click the cell and choose the current stage. Cells auto colour-code (red = not started, orange/yellow = in progress, blue = forwarded/near complete, green = fully complete) so the Department Head can scan the sheet and instantly see what needs attention.
A8: 4. % Complete column | B8: Auto-calculated from how many of the 13 tracked status fields have been filled in for that course. It's a quick completion gauge, not a substitute for reading the actual statuses.
A9: 5. Dashboard sheet | B9: Auto-summarises how many courses sit at each stage of the Course Outline, Class Test and Exam workflow steps, plus overall average completion, mighe be useful for a Department meeting snapshot.
A10: 6. Lists sheet | B10: Hidden sheet holding the dropdown option lists. Don't delete it, or the dropdowns will break. You can reorder/extend the option text there and the colours will still apply as long as the exact wording is used in the tracker.
A11: Colour legend | B11: Red = earliest stage (not started) -> Orange/Yellow = in progress -> Blue = forwarded / awaiting next step -> Green = completed / finalised for that stage.
A13: Legend swatches
A14: Not started
A15: Early progress
A16: In progress
A17: Forwarded / near complete
A18: Completed / finalised

Sheet 01_Theory Course List
A1: Type of Course | B1: SL No. | C1: Course Code | D1: Course Title | E1: Contact Hours | F1: Section | G1: Course Teacher 01 | H1: Course Teacher 02 | I1: Remarks/Notes
A2: Theory | B2: 1 | C2: BME 101 | D2: Introduction to Biomedical Engineering | E2: 3 | F2: X | G2: Dr. M. Tarik Arafat | H2: Dr. Jahid Ferdous
B3: 2 | C3: BME 201 | D3: Biomechanics | E3: 3 | F3: X | G3: Mr. Md. Abdullah Al Mamun | H3: Ms. Srija Sarker Anannya
B4: 3 | C4: BME 203 | D4: Human Physiology | E4: 3 | F4: X | G4: Ms. Tasnia Binte Mamun | H4: Ms. Chaity Chakraborty
B5: 4 | C5: BME 211 | D5: Bioelectricity | E5: 3 | F5: X | G5: Mr. Samiul Based Shuvo | H5: Mr. Sadman Sakib Himel
B6: 5 | C6: BME 205 | D6: Biofluid Mechanics and Heat Transfer | E6: 3 | F6: X | G6: Mr. Shoyad Ibn Sabur Khan Nuhash | H6: Mr. Md. Abdullah Al Mamun
B7: 6 | C7: BME 207 | D7: Biomaterials | E7: 3 | F7: X | G7: Ms. Samina Nishat Binte Akram | H7: Dr. M. Tarik Arafat
B8: 7 | C8: BME 309 | D8: Quantitative Physiology | E8: 3 | F8: X | G8: Mr. Md. Tazuddin Ahmed Akash | H8: Ms. Omi Bonik
B9: 8 | C9: BME 303 | D9: Biomedical Instrumentation and Measurements | E9: 3 | F9: X | G9: Mr. Samiul Based Shuvo | H9: Mr. Sayeed Sajjad Razin
B10: 9 | C10: BME 311 | D10: Biomedical Signals and Systems | E10: 3 | F10: X | G10: Mr. Shoyad Ibn Sabur Khan Nuhash | H10: Dr. Taufiq Hasan
B11: 10 | C11: BME 403 | D11: Medical Imaging | E11: 3 | F11: X | G11: Ms. Tasnia Binte Mamun | H11: Mr. Shoyad Ibn Sabur Khan Nuhash
B12: 11 | C12: BME 409 (Elective) | D12: Tissue Engineering and Regenerative Medicine | E12: 3 | F12: X | G12: Ms. Srija Sarker Anannya | H12: Ms. Chaity Chakraborty
B13: 12 | C13: BME 449 (Elective) | D13: Machine Learning for Biomedical Engineers | E13: 3 | F13: X | G13: Dr. Taufiq Hasan | H13: Mr. Sayeed Sajjad Razin
B14: 13 | C14: BME 441 (Elective) | D14: Neural Engineering | E14: 3 | F14: X | G14: Mr. Md. Tazuddin Ahmed Akash | H14: Mr. Samiul Based Shuvo

Sheet 02_Sessional Course List
A1: Type of Course | B1: SL No. | C1: Course Code | D1: Course Title | E1: Contact Hours | F1: Section | G1: Course Teacher 01 | H1: Course Teacher 02 | I1: Course Teacher 03 | J1: Course Teacher 04 | K1: Course Teacher 05 | L1: Remarks/Notes
A2: Sessional | B2: 1 | C2: BME 202 | D2: Biomechanics Sessional | E2: 1.5 | F2: A1 | G2: Mr. Md. Abdullah Al Mamun | H2: Ms. Srija Sarker Anannya | I2: Ms. Chaity Chakraborty
F3: A2 | G3: Mr. Md. Abdullah Al Mamun | H3: Ms. Srija Sarker Anannya | I3: Ms. Chaity Chakraborty
B4: 2 | C4: BME 204 | D4: Human Physiology Sessional | E4: 3 | F4: A1 | G4: Mr. Shoyad Ibn Sabur Khan Nuhash | H4: Ms. Samina Nishat Binte Akram | I4: Ms. Tasnia Binte Mamun | J4: Ms. Chaity Chakraborty
F5: A2 | G5: Mr. Shoyad Ibn Sabur Khan Nuhash | H5: Ms. Samina Nishat Binte Akram | I5: Ms. Tasnia Binte Mamun | J5: Ms. Omi Bonik
B6: 3 | C6: BME 206 | D6: Biofluid Mechanics and Heat Transfer Sessional | E6: 3 | F6: A1 | G6: Mr. Shoyad Ibn Sabur Khan Nuhash | H6: Mr. Md. Abdullah Al Mamun | I6: Ms. Omi Bonik
F7: A2 | G7: Mr. Shoyad Ibn Sabur Khan Nuhash | H7: Mr. Md. Abdullah Al Mamun | I7: Mr. Sadman Sakib Himel
B8: 4 | C8: BME 208 | D8: Biomaterials Sessional | E8: 3 | F8: A1 | G8: Ms. Samina Nishat Binte Akram | H8: Ms. Srija Sarker Anannya | I8: Ms. Chaity Chakraborty
F9: A2 | G9: Ms. Samina Nishat Binte Akram | H9: Ms. Srija Sarker Anannya | I9: Ms. Chaity Chakraborty
B10: 5 | C10: BME 210 | D10: Numerial Techniques Sessional | E10: 1.5 | F10: A1 | G10: Mr. Md. Tazuddin Ahmed Akash | H10: Mr. Sayeed Sajjad Razin | I10: Mr. Sadman Sakib Himel
F11: A2 | G11: Mr. Md. Tazuddin Ahmed Akash | H11: Mr. Sayeed Sajjad Razin | I11: Mr. Sadman Sakib Himel
B12: 6 | C12: BME 300 | D12: Biomedical Engineering Design - I | E12: 3 | F12: A1 | G12: Mr. Shoyad Ibn Sabur Khan Nuhash | H12: Mr. Samiul Based Shuvo | I12: Mr. Md. Abdullah Al Mamun | J12: Ms. Samina Nishat Binte Akram | K12: Ms. Chaity Chakraborty
F13: A2 | G13: Mr. Samiul Based Shuvo | H13: Mr. Md. Tazuddin Ahmed Akash | I13: Mr. Md. Abdullah Al Mamun | J13: Ms. Srija Sarker Anannya | K13: Mr. Sayeed Sajjad Razin
B14: 7 | C14: BME 304 | D14: Biomedical Instrumentation and Measurements Sessional | E14: 3 | F14: A1 | G14: Mr. Samiul Based Shuvo | H14: Mr. Sayeed Sajjad Razin | I14: Mr. Sadman Sakib Himel
F15: A2 | G15: Mr. Samiul Based Shuvo | H15: Mr. Sayeed Sajjad Razin | I15: Mr. Sadman Sakib Himel
B16: 8 | C16: BME 310 | D16: Communication Protocol for Biomedical Instruments Sessional | E16: 3 | F16: A1 | G16: Mr. Md. Tazuddin Ahmed Akash | H16: Mr. Sayeed Sajjad Razin | I16: Mr. Sadman Sakib Himel
F17: A2 | G17: Ms. Tasnia Binte Mamun | H17: Ms. Omi Bonik | I17: Mr. Sadman Sakib Himel
B18: 9 | C18: BME 404 | D18: Medical Imaging Sessional | E18: 3 | F18: A1 | G18: Mr. Md. Tazuddin Ahmed Akash | H18: Ms. Tasnia Binte Mamun | I18: Ms. Omi Bonik
F19: A2 | G19: Mr. Md. Tazuddin Ahmed Akash | H19: Ms. Tasnia Binte Mamun | I19: Ms. Omi Bonik
B20: 10 | C20: BME 400 | D20: Thesis | E20: 6 | F20: X | G20: Dr. M. Tarik Arafat | H20: Dr. Taufiq Hasan | I20: Dr. Jahid Ferdous

Sheet 03_Course Outline Tracker
A1: Type of Course | B1: ='01_Theory Course List'!B1 -> SL No. | C1: ='01_Theory Course List'!C1 -> Course Code | D1: ='01_Theory Course List'!D1 -> Course Title | E1: Section | F1: Course Teacher 01 | G1: Course Teacher 02 | H1: Course Teacher 03 | I1: Course Teacher 04 | J1: Course Teacher 05 | K1: Course Outline Status | L1: Outline Sharing Deadline | M1: Remarks/Notes
A2: Theory | B2: ='01_Theory Course List'!B2 -> 1 | C2: ='01_Theory Course List'!C2 -> BME 101 | D2: ='01_Theory Course List'!D2 -> Introduction to Biomedical Engineering | E2: X | F2: =IFERROR(INDEX('01_Theory Course List'!$G$2:$G$479,MATCH(C2,'01_Theory Course List'!$C$2:$C$479,0)),"") -> Dr. M. Tarik Arafat | G2: =IFERROR(INDEX('01_Theory Course List'!$H$2:$H$479,MATCH(C2,'01_Theory Course List'!$C$2:$C$479,0)),"") -> Dr. Jahid Ferdous | K2: Shared with Students | L2: 46200
B3: ='01_Theory Course List'!B3 -> 2 | C3: ='01_Theory Course List'!C3 -> BME 201 | D3: ='01_Theory Course List'!D3 -> Biomechanics | F3: =IFERROR(INDEX('01_Theory Course List'!$G$2:$G$479,MATCH(C3,'01_Theory Course List'!$C$2:$C$479,0)),"") -> Mr. Md. Abdullah Al Mamun | G3: =IFERROR(INDEX('01_Theory Course List'!$H$2:$H$479,MATCH(C3,'01_Theory Course List'!$C$2:$C$479,0)),"") -> Ms. Srija Sarker Anannya | K3: Shared with Students
B4: ='01_Theory Course List'!B4 -> 3 | C4: ='01_Theory Course List'!C4 -> BME 203 | D4: ='01_Theory Course List'!D4 -> Human Physiology | F4: =IFERROR(INDEX('01_Theory Course List'!$G$2:$G$479,MATCH(C4,'01_Theory Course List'!$C$2:$C$479,0)),"") -> Ms. Tasnia Binte Mamun | G4: =IFERROR(INDEX('01_Theory Course List'!$H$2:$H$479,MATCH(C4,'01_Theory Course List'!$C$2:$C$479,0)),"") -> Ms. Chaity Chakraborty | K4: Shared with Students
B5: ='01_Theory Course List'!B5 -> 4 | C5: ='01_Theory Course List'!C5 -> BME 211 | D5: ='01_Theory Course List'!D5 -> Bioelectricity | F5: =IFERROR(INDEX('01_Theory Course List'!$G$2:$G$479,MATCH(C5,'01_Theory Course List'!$C$2:$C$479,0)),"") -> Mr. Samiul Based Shuvo | G5: =IFERROR(INDEX('01_Theory Course List'!$H$2:$H$479,MATCH(C5,'01_Theory Course List'!$C$2:$C$479,0)),"") -> Mr. Sadman Sakib Himel | K5: Shared with Students
B6: ='01_Theory Course List'!B6 -> 5 | C6: ='01_Theory Course List'!C6 -> BME 205 | D6: ='01_Theory Course List'!D6 -> Biofluid Mechanics and Heat Transfer | F6: =IFERROR(INDEX('01_Theory Course List'!$G$2:$G$479,MATCH(C6,'01_Theory Course List'!$C$2:$C$479,0)),"") -> Mr. Shoyad Ibn Sabur Khan Nuhash | G6: =IFERROR(INDEX('01_Theory Course List'!$H$2:$H$479,MATCH(C6,'01_Theory Course List'!$C$2:$C$479,0)),"") -> Mr. Md. Abdullah Al Mamun | K6: Shared with Students
B7: ='01_Theory Course List'!B7 -> 6 | C7: ='01_Theory Course List'!C7 -> BME 207 | D7: ='01_Theory Course List'!D7 -> Biomaterials | F7: =IFERROR(INDEX('01_Theory Course List'!$G$2:$G$479,MATCH(C7,'01_Theory Course List'!$C$2:$C$479,0)),"") -> Ms. Samina Nishat Binte Akram | G7: =IFERROR(INDEX('01_Theory Course List'!$H$2:$H$479,MATCH(C7,'01_Theory Course List'!$C$2:$C$479,0)),"") -> Dr. M. Tarik Arafat | K7: Shared with Students
B8: ='01_Theory Course List'!B8 -> 7 | C8: ='01_Theory Course List'!C8 -> BME 309 | D8: ='01_Theory Course List'!D8 -> Quantitative Physiology | F8: =IFERROR(INDEX('01_Theory Course List'!$G$2:$G$479,MATCH(C8,'01_Theory Course List'!$C$2:$C$479,0)),"") -> Mr. Md. Tazuddin Ahmed Akash | G8: =IFERROR(INDEX('01_Theory Course List'!$H$2:$H$479,MATCH(C8,'01_Theory Course List'!$C$2:$C$479,0)),"") -> Ms. Omi Bonik
B9: ='01_Theory Course List'!B9 -> 8 | C9: ='01_Theory Course List'!C9 -> BME 303 | D9: ='01_Theory Course List'!D9 -> Biomedical Instrumentation and Measurements | F9: =IFERROR(INDEX('01_Theory Course List'!$G$2:$G$479,MATCH(C9,'01_Theory Course List'!$C$2:$C$479,0)),"") -> Mr. Samiul Based Shuvo | G9: =IFERROR(INDEX('01_Theory Course List'!$H$2:$H$479,MATCH(C9,'01_Theory Course List'!$C$2:$C$479,0)),"") -> Mr. Sayeed Sajjad Razin | K9: Shared with Students
B10: ='01_Theory Course List'!B10 -> 9 | C10: ='01_Theory Course List'!C10 -> BME 311 | D10: ='01_Theory Course List'!D10 -> Biomedical Signals and Systems | F10: =IFERROR(INDEX('01_Theory Course List'!$G$2:$G$479,MATCH(C10,'01_Theory Course List'!$C$2:$C$479,0)),"") -> Mr. Shoyad Ibn Sabur Khan Nuhash | G10: =IFERROR(INDEX('01_Theory Course List'!$H$2:$H$479,MATCH(C10,'01_Theory Course List'!$C$2:$C$479,0)),"") -> Dr. Taufiq Hasan | K10: Shared with Students
B11: ='01_Theory Course List'!B11 -> 10 | C11: ='01_Theory Course List'!C11 -> BME 403 | D11: ='01_Theory Course List'!D11 -> Medical Imaging | F11: =IFERROR(INDEX('01_Theory Course List'!$G$2:$G$479,MATCH(C11,'01_Theory Course List'!$C$2:$C$479,0)),"") -> Ms. Tasnia Binte Mamun | G11: =IFERROR(INDEX('01_Theory Course List'!$H$2:$H$479,MATCH(C11,'01_Theory Course List'!$C$2:$C$479,0)),"") -> Mr. Shoyad Ibn Sabur Khan Nuhash | K11: Shared with Students
B12: ='01_Theory Course List'!B12 -> 11 | C12: ='01_Theory Course List'!C12 -> BME 409 (Elective) | D12: ='01_Theory Course List'!D12 -> Tissue Engineering and Regenerative Medicine | F12: =IFERROR(INDEX('01_Theory Course List'!$G$2:$G$479,MATCH(C12,'01_Theory Course List'!$C$2:$C$479,0)),"") -> Ms. Srija Sarker Anannya | G12: =IFERROR(INDEX('01_Theory Course List'!$H$2:$H$479,MATCH(C12,'01_Theory Course List'!$C$2:$C$479,0)),"") -> Ms. Chaity Chakraborty | K12: Shared with Students
B13: ='01_Theory Course List'!B13 -> 12 | C13: ='01_Theory Course List'!C13 -> BME 449 (Elective) | D13: ='01_Theory Course List'!D13 -> Machine Learning for Biomedical Engineers | F13: =IFERROR(INDEX('01_Theory Course List'!$G$2:$G$479,MATCH(C13,'01_Theory Course List'!$C$2:$C$479,0)),"") -> Dr. Taufiq Hasan | G13: =IFERROR(INDEX('01_Theory Course List'!$H$2:$H$479,MATCH(C13,'01_Theory Course List'!$C$2:$C$479,0)),"") -> Mr. Sayeed Sajjad Razin | K13: Shared with Students
B14: ='01_Theory Course List'!B14 -> 13 | C14: ='01_Theory Course List'!C14 -> BME 441 (Elective) | D14: ='01_Theory Course List'!D14 -> Neural Engineering | F14: =IFERROR(INDEX('01_Theory Course List'!$G$2:$G$479,MATCH(C14,'01_Theory Course List'!$C$2:$C$479,0)),"") -> Mr. Md. Tazuddin Ahmed Akash | G14: =IFERROR(INDEX('01_Theory Course List'!$H$2:$H$479,MATCH(C14,'01_Theory Course List'!$C$2:$C$479,0)),"") -> Mr. Samiul Based Shuvo | K14: Shared with Students
A15: Sessional | B15: 14 | C15: BME 202 | D15: Biomechanics Sessional | E15: A1 | F15: Mr. Md. Abdullah Al Mamun | G15: Ms. Srija Sarker Anannya | H15: Ms. Chaity Chakraborty | K15: Shared with Students
E16: A2 | F16: Mr. Md. Abdullah Al Mamun | G16: Ms. Srija Sarker Anannya | H16: Ms. Chaity Chakraborty
B17: 15 | C17: BME 204 | D17: Human Physiology Sessional | E17: A1 | F17: Mr. Shoyad Ibn Sabur Khan Nuhash | G17: Ms. Samina Nishat Binte Akram | H17: Ms. Tasnia Binte Mamun | I17: Ms. Chaity Chakraborty | K17: Shared with Students
E18: A2 | F18: Mr. Shoyad Ibn Sabur Khan Nuhash | G18: Ms. Samina Nishat Binte Akram | H18: Ms. Tasnia Binte Mamun | I18: Ms. Omi Bonik
B19: 16 | C19: BME 206 | D19: Biofluid Mechanics and Heat Transfer Sessional | E19: A1 | F19: Mr. Shoyad Ibn Sabur Khan Nuhash | G19: Mr. Md. Abdullah Al Mamun | H19: Ms. Omi Bonik | K19: Shared with Students
E20: A2 | F20: Mr. Shoyad Ibn Sabur Khan Nuhash | G20: Mr. Md. Abdullah Al Mamun | H20: Mr. Sadman Sakib Himel
B21: 17 | C21: BME 208 | D21: Biomaterials Sessional | E21: A1 | F21: Ms. Samina Nishat Binte Akram | G21: Ms. Srija Sarker Anannya | H21: Ms. Chaity Chakraborty | K21: Shared with Students
E22: A2 | F22: Ms. Samina Nishat Binte Akram | G22: Ms. Srija Sarker Anannya | H22: Ms. Chaity Chakraborty
B23: 18 | C23: BME 210 | D23: Numerial Techniques Sessional | E23: A1 | F23: Mr. Md. Tazuddin Ahmed Akash | G23: Mr. Sayeed Sajjad Razin | H23: Mr. Sadman Sakib Himel | K23: Shared with Students
E24: A2 | F24: Mr. Md. Tazuddin Ahmed Akash | G24: Mr. Sayeed Sajjad Razin | H24: Mr. Sadman Sakib Himel
B25: 19 | C25: BME 300 | D25: Biomedical Engineering Design - I | E25: A1 | F25: Mr. Shoyad Ibn Sabur Khan Nuhash | G25: Mr. Samiul Based Shuvo | H25: Mr. Md. Abdullah Al Mamun | I25: Ms. Samina Nishat Binte Akram | J25: Ms. Chaity Chakraborty | K25: Shared with Students
E26: A2 | F26: Mr. Samiul Based Shuvo | G26: Mr. Md. Tazuddin Ahmed Akash | H26: Mr. Md. Abdullah Al Mamun | I26: Ms. Srija Sarker Anannya | J26: Mr. Sayeed Sajjad Razin
B27: 20 | C27: BME 304 | D27: Biomedical Instrumentation and Measurements Sessional | E27: A1 | F27: Mr. Samiul Based Shuvo | G27: Mr. Sayeed Sajjad Razin | H27: Mr. Sadman Sakib Himel | K27: Shared with Students
E28: A2 | F28: Mr. Samiul Based Shuvo | G28: Mr. Sayeed Sajjad Razin | H28: Mr. Sadman Sakib Himel
B29: 21 | C29: BME 310 | D29: Communication Protocol for Biomedical Instruments Sessional | E29: A1 | F29: Mr. Md. Tazuddin Ahmed Akash | G29: Mr. Sayeed Sajjad Razin | H29: Mr. Sadman Sakib Himel | K29: Shared with Students
E30: A2 | F30: Ms. Tasnia Binte Mamun | G30: Ms. Omi Bonik | H30: Mr. Sadman Sakib Himel
B31: 22 | C31: BME 404 | D31: Medical Imaging Sessional | E31: A1 | F31: Mr. Md. Tazuddin Ahmed Akash | G31: Ms. Tasnia Binte Mamun | H31: Ms. Omi Bonik | K31: Shared with Students
E32: A2 | F32: Mr. Md. Tazuddin Ahmed Akash | G32: Ms. Tasnia Binte Mamun | H32: Ms. Omi Bonik
B33: 23 | C33: BME 400 | D33: Thesis | E33: X | F33: Dr. M. Tarik Arafat | G33: Dr. Taufiq Hasan | H33: Dr. Jahid Ferdous

Sheet 04_Class Test Tracker
A1: ='01_Theory Course List'!B1 -> SL No. | B1: ='01_Theory Course List'!C1 -> Course Code | C1: ='01_Theory Course List'!D1 -> Course Title | D1: Course Teacher 01 | E1: Course Teacher 02 | F1: CT 01 Date | G1: CT 01 Status | H1: CT 02 Date | I1: CT 02 Status | J1: CT 03 Date | K1: CT 03 Status | L1: CT 04 Date | M1: CT 04 Status | N1: CT 05 Date | O1: CT 05 Status | P1: Remarks/Notes
A2: ='01_Theory Course List'!B2 -> 1 | B2: ='01_Theory Course List'!C2 -> BME 101 | C2: ='01_Theory Course List'!D2 -> Introduction to Biomedical Engineering | D2: =IFERROR(INDEX('01_Theory Course List'!$G$2:$G$479,MATCH(B2,'01_Theory Course List'!$C$2:$C$479,0)),"") -> Dr. M. Tarik Arafat | E2: =IFERROR(INDEX('01_Theory Course List'!$H$2:$H$479,MATCH(B2,'01_Theory Course List'!$C$2:$C$479,0)),"") -> Dr. Jahid Ferdous | G2: Marks Published | I2: Marks Published | J2: 18/08/2026 | K2: Marks Published
A3: ='01_Theory Course List'!B3 -> 2 | B3: ='01_Theory Course List'!C3 -> BME 201 | C3: ='01_Theory Course List'!D3 -> Biomechanics | D3: =IFERROR(INDEX('01_Theory Course List'!$G$2:$G$479,MATCH(B3,'01_Theory Course List'!$C$2:$C$479,0)),"") -> Mr. Md. Abdullah Al Mamun | E3: =IFERROR(INDEX('01_Theory Course List'!$H$2:$H$479,MATCH(B3,'01_Theory Course List'!$C$2:$C$479,0)),"") -> Ms. Srija Sarker Anannya
A4: ='01_Theory Course List'!B4 -> 3 | B4: ='01_Theory Course List'!C4 -> BME 203 | C4: ='01_Theory Course List'!D4 -> Human Physiology | D4: =IFERROR(INDEX('01_Theory Course List'!$G$2:$G$479,MATCH(B4,'01_Theory Course List'!$C$2:$C$479,0)),"") -> Ms. Tasnia Binte Mamun | E4: =IFERROR(INDEX('01_Theory Course List'!$H$2:$H$479,MATCH(B4,'01_Theory Course List'!$C$2:$C$479,0)),"") -> Ms. Chaity Chakraborty | F4: Saturday, July 18, 2026 | G4: Marks Published | H4: Monday, August 17, 2026 | I4: Marks Published
A5: ='01_Theory Course List'!B5 -> 4 | B5: ='01_Theory Course List'!C5 -> BME 211 | C5: ='01_Theory Course List'!D5 -> Bioelectricity | D5: =IFERROR(INDEX('01_Theory Course List'!$G$2:$G$479,MATCH(B5,'01_Theory Course List'!$C$2:$C$479,0)),"") -> Mr. Samiul Based Shuvo | E5: =IFERROR(INDEX('01_Theory Course List'!$H$2:$H$479,MATCH(B5,'01_Theory Course List'!$C$2:$C$479,0)),"") -> Mr. Sadman Sakib Himel | G5: Scripts Under Examination | I5: CT Scheduled | J5: 25/08/2026 | K5: Marks Published
A6: ='01_Theory Course List'!B6 -> 5 | B6: ='01_Theory Course List'!C6 -> BME 205 | C6: ='01_Theory Course List'!D6 -> Biofluid Mechanics and Heat Transfer | D6: =IFERROR(INDEX('01_Theory Course List'!$G$2:$G$479,MATCH(B6,'01_Theory Course List'!$C$2:$C$479,0)),"") -> Mr. Shoyad Ibn Sabur Khan Nuhash | E6: =IFERROR(INDEX('01_Theory Course List'!$H$2:$H$479,MATCH(B6,'01_Theory Course List'!$C$2:$C$479,0)),"") -> Mr. Md. Abdullah Al Mamun | F6: 46224 | G6: Marks Published | H6: 46253 | I6: Marks Published
A7: ='01_Theory Course List'!B7 -> 6 | B7: ='01_Theory Course List'!C7 -> BME 207 | C7: ='01_Theory Course List'!D7 -> Biomaterials | D7: =IFERROR(INDEX('01_Theory Course List'!$G$2:$G$479,MATCH(B7,'01_Theory Course List'!$C$2:$C$479,0)),"") -> Ms. Samina Nishat Binte Akram | E7: =IFERROR(INDEX('01_Theory Course List'!$H$2:$H$479,MATCH(B7,'01_Theory Course List'!$C$2:$C$479,0)),"") -> Dr. M. Tarik Arafat | F7: Tuesday, July 7, 2026 | G7: Marks Published | H7: 46231 | I7: Marks Published
A8: ='01_Theory Course List'!B8 -> 7 | B8: ='01_Theory Course List'!C8 -> BME 309 | C8: ='01_Theory Course List'!D8 -> Quantitative Physiology | D8: =IFERROR(INDEX('01_Theory Course List'!$G$2:$G$479,MATCH(B8,'01_Theory Course List'!$C$2:$C$479,0)),"") -> Mr. Md. Tazuddin Ahmed Akash | E8: =IFERROR(INDEX('01_Theory Course List'!$H$2:$H$479,MATCH(B8,'01_Theory Course List'!$C$2:$C$479,0)),"") -> Ms. Omi Bonik
A9: ='01_Theory Course List'!B9 -> 8 | B9: ='01_Theory Course List'!C9 -> BME 303 | C9: ='01_Theory Course List'!D9 -> Biomedical Instrumentation and Measurements | D9: =IFERROR(INDEX('01_Theory Course List'!$G$2:$G$479,MATCH(B9,'01_Theory Course List'!$C$2:$C$479,0)),"") -> Mr. Samiul Based Shuvo | E9: =IFERROR(INDEX('01_Theory Course List'!$H$2:$H$479,MATCH(B9,'01_Theory Course List'!$C$2:$C$479,0)),"") -> Mr. Sayeed Sajjad Razin | G9: Scripts Under Examination | I9: Scripts Under Examination
A10: ='01_Theory Course List'!B10 -> 9 | B10: ='01_Theory Course List'!C10 -> BME 311 | C10: ='01_Theory Course List'!D10 -> Biomedical Signals and Systems | D10: =IFERROR(INDEX('01_Theory Course List'!$G$2:$G$479,MATCH(B10,'01_Theory Course List'!$C$2:$C$479,0)),"") -> Mr. Shoyad Ibn Sabur Khan Nuhash | E10: =IFERROR(INDEX('01_Theory Course List'!$H$2:$H$479,MATCH(B10,'01_Theory Course List'!$C$2:$C$479,0)),"") -> Dr. Taufiq Hasan | F10: 46218 | G10: Scripts Under Examination | H10: 46258 | I10: Scripts Under Examination
A11: ='01_Theory Course List'!B11 -> 10 | B11: ='01_Theory Course List'!C11 -> BME 403 | C11: ='01_Theory Course List'!D11 -> Medical Imaging | D11: =IFERROR(INDEX('01_Theory Course List'!$G$2:$G$479,MATCH(B11,'01_Theory Course List'!$C$2:$C$479,0)),"") -> Ms. Tasnia Binte Mamun | E11: =IFERROR(INDEX('01_Theory Course List'!$H$2:$H$479,MATCH(B11,'01_Theory Course List'!$C$2:$C$479,0)),"") -> Mr. Shoyad Ibn Sabur Khan Nuhash | F11: July 21,2026 | G11: Marks Published | H11: August 17,2026 | I11: Marks Published
A12: ='01_Theory Course List'!B12 -> 11 | B12: ='01_Theory Course List'!C12 -> BME 409 (Elective) | C12: ='01_Theory Course List'!D12 -> Tissue Engineering and Regenerative Medicine | D12: =IFERROR(INDEX('01_Theory Course List'!$G$2:$G$479,MATCH(B12,'01_Theory Course List'!$C$2:$C$479,0)),"") -> Ms. Srija Sarker Anannya | E12: =IFERROR(INDEX('01_Theory Course List'!$H$2:$H$479,MATCH(B12,'01_Theory Course List'!$C$2:$C$479,0)),"") -> Ms. Chaity Chakraborty | F12: Tuesday, July 21, 2026 | G12: Marks Published | H12: Saturday, August 22, 2026 | I12: Marks Published
A13: ='01_Theory Course List'!B13 -> 12 | B13: ='01_Theory Course List'!C13 -> BME 449 (Elective) | C13: ='01_Theory Course List'!D13 -> Machine Learning for Biomedical Engineers | D13: =IFERROR(INDEX('01_Theory Course List'!$G$2:$G$479,MATCH(B13,'01_Theory Course List'!$C$2:$C$479,0)),"") -> Dr. Taufiq Hasan | E13: =IFERROR(INDEX('01_Theory Course List'!$H$2:$H$479,MATCH(B13,'01_Theory Course List'!$C$2:$C$479,0)),"") -> Mr. Sayeed Sajjad Razin | F13: 46218 | G13: Marks Published | H13: 46265 | I13: CT Scheduled
A14: ='01_Theory Course List'!B14 -> 13 | B14: ='01_Theory Course List'!C14 -> BME 441 (Elective) | C14: ='01_Theory Course List'!D14 -> Neural Engineering | D14: =IFERROR(INDEX('01_Theory Course List'!$G$2:$G$479,MATCH(B14,'01_Theory Course List'!$C$2:$C$479,0)),"") -> Mr. Md. Tazuddin Ahmed Akash | E14: =IFERROR(INDEX('01_Theory Course List'!$H$2:$H$479,MATCH(B14,'01_Theory Course List'!$C$2:$C$479,0)),"") -> Mr. Samiul Based Shuvo | G14: Scripts Under Examination | I14: Scripts Under Examination

Sheet 05_Sessional Assessment Tracker
A1: ='02_Sessional Course List'!A1 -> Type of Course | B1: ='02_Sessional Course List'!B1 -> SL No. | C1: ='02_Sessional Course List'!C1 -> Course Code | D1: ='02_Sessional Course List'!D1 -> Course Title | E1: ='02_Sessional Course List'!E1 -> Contact Hours | F1: ='02_Sessional Course List'!F1 -> Section | G1: Type of Evaluation | H1: Evaluation Date | I1: Evaluation Status | J1: Type of Evaluation | K1: Evaluation Date | L1: Evaluation Status | M1: Type of Evaluation | N1: Evaluation Date | O1: Evaluation Status | P1: Type of Evaluation | Q1: Evaluation Date | R1: Evaluation Status | S1: Type of Evaluation | T1: Evaluation Date | U1: Evaluation Status | V1: Type of Evaluation | W1: Evaluation Date | X1: Evaluation Status | Y1: Type of Evaluation | Z1: Evaluation Date | AA1: Evaluation Status | AB1: Type of Evaluation | AC1: Evaluation Date | AD1: Evaluation Status | AE1: Type of Evaluation | AF1: Evaluation Date | AG1: Evaluation Status | AH1: Type of Evaluation | AI1: Evaluation Date | AJ1: Evaluation Status | AK1: Type of Evaluation | AL1: Evaluation Date | AM1: Evaluation Status | AN1: Type of Evaluation | AO1: Evaluation Date | AP1: Evaluation Status | AQ1: Type of Evaluation | AR1: Evaluation Date | AS1: Evaluation Status | AT1: Type of Evaluation | AU1: Evaluation Date | AV1: Evaluation Status | AW1: Type of Evaluation | AX1: Evaluation Date | AY1: Evaluation Status | AZ1: Type of Evaluation | BA1: Evaluation Date | BB1: Evaluation Status | BC1: Type of Evaluation | BD1: Evaluation Date | BE1: Evaluation Status | BF1: Type of Evaluation | BG1: Evaluation Date | BH1: Evaluation Status | BI1: Type of Evaluation | BJ1: Evaluation Date | BK1: Evaluation Status | BL1: Type of Evaluation | BM1: Evaluation Date | BN1: Evaluation Status | BO1: Type of Evaluation | BP1: Evaluation Date | BQ1: Evaluation Status | BR1: Type of Evaluation | BS1: Evaluation Date | BT1: Evaluation Status | BU1: Type of Evaluation | BV1: Evaluation Date | BW1: Evaluation Status | BX1: Type of Evaluation | BY1: Evaluation Date | BZ1: Evaluation Status | CA1: Type of Evaluation | CB1: Evaluation Date | CC1: Evaluation Status | CD1: Remarks/Notes
A2: ='02_Sessional Course List'!A2 -> Sessional | B2: ='02_Sessional Course List'!B2 -> 1 | C2: ='02_Sessional Course List'!C2 -> BME 202 | D2: ='02_Sessional Course List'!D2 -> Biomechanics Sessional | E2: ='02_Sessional Course List'!E2 -> 1.5 | F2: ='02_Sessional Course List'!F2 -> A1
F3: ='02_Sessional Course List'!F3 -> A2
B4: ='02_Sessional Course List'!B4 -> 2 | C4: ='02_Sessional Course List'!C4 -> BME 204 | D4: ='02_Sessional Course List'!D4 -> Human Physiology Sessional | E4: ='02_Sessional Course List'!E4 -> 3 | F4: ='02_Sessional Course List'!F4 -> A1 | G4: Continuous Assessment Quiz 01 | I4: Evaluation Taken
F5: ='02_Sessional Course List'!F5 -> A2
B6: ='02_Sessional Course List'!B6 -> 3 | C6: ='02_Sessional Course List'!C6 -> BME 206 | D6: ='02_Sessional Course List'!D6 -> Biofluid Mechanics and Heat Transfer Sessional | E6: ='02_Sessional Course List'!E6 -> 3 | F6: ='02_Sessional Course List'!F6 -> A1 | G6: Lab Test 01 | H6: 46228 | I6: Marks Uploaded in Excel
F7: ='02_Sessional Course List'!F7 -> A2
B8: ='02_Sessional Course List'!B8 -> 4 | C8: ='02_Sessional Course List'!C8 -> BME 208 | D8: ='02_Sessional Course List'!D8 -> Biomaterials Sessional | E8: ='02_Sessional Course List'!E8 -> 3 | F8: ='02_Sessional Course List'!F8 -> A1 | G8: Continuous Assessment Quiz 01 | I8: Evaluation Taken | J8: Conitnuous Assessment 02 | L8: Evaluation Taken | M8: Continuous Assessment 03 | N8: Sunday, Auguest 23, 2026 | O8: Evaluation Taken
F9: ='02_Sessional Course List'!F9 -> A2
B10: ='02_Sessional Course List'!B10 -> 5 | C10: ='02_Sessional Course List'!C10 -> BME 210 | D10: ='02_Sessional Course List'!D10 -> Numerial Techniques Sessional | E10: ='02_Sessional Course List'!E10 -> 1.5 | F10: ='02_Sessional Course List'!F10 -> A1 | N10: 46259
F11: ='02_Sessional Course List'!F11 -> A2
B12: ='02_Sessional Course List'!B12 -> 6 | C12: ='02_Sessional Course List'!C12 -> BME 300 | D12: ='02_Sessional Course List'!D12 -> Biomedical Engineering Design - I | E12: ='02_Sessional Course List'!E12 -> 3 | F12: ='02_Sessional Course List'!F12 -> A1
F13: ='02_Sessional Course List'!F13 -> A2
B14: ='02_Sessional Course List'!B14 -> 7 | C14: ='02_Sessional Course List'!C14 -> BME 304 | D14: ='02_Sessional Course List'!D14 -> Biomedical Instrumentation and Measurements Sessional | E14: ='02_Sessional Course List'!E14 -> 3 | F14: ='02_Sessional Course List'!F14 -> A1 | H14: 46236 | I14: Marks Uploaded in Excel | J14: Lab Test 01
F15: ='02_Sessional Course List'!F15 -> A2
B16: ='02_Sessional Course List'!B16 -> 8 | C16: ='02_Sessional Course List'!C16 -> BME 310 | D16: ='02_Sessional Course List'!D16 -> Communication Protocol for Biomedical Instruments Sessional | E16: ='02_Sessional Course List'!E16 -> 3 | F16: ='02_Sessional Course List'!F16 -> A1 | G16: Continuous Assessment 01 | I16: Marks Uploaded in Excel | J16: Conitnuous Assessment 02 | L16: Marks Uploaded in Excel | M16: Continuous Assessment 03 | O16: Marks Uploaded in Excel | P16: Lab Test 01 | R16: Marking Complete
F17: ='02_Sessional Course List'!F17 -> A2
B18: ='02_Sessional Course List'!B18 -> 9 | C18: ='02_Sessional Course List'!C18 -> BME 404 | D18: ='02_Sessional Course List'!D18 -> Medical Imaging Sessional | E18: ='02_Sessional Course List'!E18 -> 3 | F18: ='02_Sessional Course List'!F18 -> A1 | G18: Continuous Assessment 01 | I18: Marks Uploaded in Excel | J18: Conitnuous Assessment 02 | L18: Marking Complete | M18: Lab Test 01 | O18: Marking Complete
F19: ='02_Sessional Course List'!F19 -> A2
B20: ='02_Sessional Course List'!B20 -> 10 | C20: ='02_Sessional Course List'!C20 -> BME 400 | D20: ='02_Sessional Course List'!D20 -> Thesis | E20: ='02_Sessional Course List'!E20 -> 6 | F20: ='02_Sessional Course List'!F20 -> X

Sheet 06_Feedback Tracker
A1: Type of Course | B1: ='01_Theory Course List'!B1 -> SL No. | C1: ='01_Theory Course List'!C1 -> Course Code | D1: ='01_Theory Course List'!D1 -> Course Title | E1: Section | F1: Course Teacher 01 | G1: Course Teacher 02 | H1: Course Teacher 03 | I1: Course Teacher 04 | J1: Course Teacher 05 | K1: Student Feedback Status | L1: Student Reminder Start Date | M1: Feedback Submission Deadline | N1: Remarks/Notes
A2: Theory | B2: ='01_Theory Course List'!B2 -> 1 | C2: ='01_Theory Course List'!C2 -> BME 101 | D2: ='01_Theory Course List'!D2 -> Introduction to Biomedical Engineering | E2: X | F2: =IFERROR(INDEX('01_Theory Course List'!$G$2:$G$479,MATCH(C2,'01_Theory Course List'!$C$2:$C$479,0)),"") -> Dr. M. Tarik Arafat | G2: =IFERROR(INDEX('01_Theory Course List'!$H$2:$H$479,MATCH(C2,'01_Theory Course List'!$C$2:$C$479,0)),"") -> Dr. Jahid Ferdous | L2: 46288 | M2: 46297
B3: ='01_Theory Course List'!B3 -> 2 | C3: ='01_Theory Course List'!C3 -> BME 201 | D3: ='01_Theory Course List'!D3 -> Biomechanics | F3: =IFERROR(INDEX('01_Theory Course List'!$G$2:$G$479,MATCH(C3,'01_Theory Course List'!$C$2:$C$479,0)),"") -> Mr. Md. Abdullah Al Mamun | G3: =IFERROR(INDEX('01_Theory Course List'!$H$2:$H$479,MATCH(C3,'01_Theory Course List'!$C$2:$C$479,0)),"") -> Ms. Srija Sarker Anannya
B4: ='01_Theory Course List'!B4 -> 3 | C4: ='01_Theory Course List'!C4 -> BME 203 | D4: ='01_Theory Course List'!D4 -> Human Physiology | F4: =IFERROR(INDEX('01_Theory Course List'!$G$2:$G$479,MATCH(C4,'01_Theory Course List'!$C$2:$C$479,0)),"") -> Ms. Tasnia Binte Mamun | G4: =IFERROR(INDEX('01_Theory Course List'!$H$2:$H$479,MATCH(C4,'01_Theory Course List'!$C$2:$C$479,0)),"") -> Ms. Chaity Chakraborty
B5: ='01_Theory Course List'!B5 -> 4 | C5: ='01_Theory Course List'!C5 -> BME 211 | D5: ='01_Theory Course List'!D5 -> Bioelectricity | F5: =IFERROR(INDEX('01_Theory Course List'!$G$2:$G$479,MATCH(C5,'01_Theory Course List'!$C$2:$C$479,0)),"") -> Mr. Samiul Based Shuvo | G5: =IFERROR(INDEX('01_Theory Course List'!$H$2:$H$479,MATCH(C5,'01_Theory Course List'!$C$2:$C$479,0)),"") -> Mr. Sadman Sakib Himel
B6: ='01_Theory Course List'!B6 -> 5 | C6: ='01_Theory Course List'!C6 -> BME 205 | D6: ='01_Theory Course List'!D6 -> Biofluid Mechanics and Heat Transfer | F6: =IFERROR(INDEX('01_Theory Course List'!$G$2:$G$479,MATCH(C6,'01_Theory Course List'!$C$2:$C$479,0)),"") -> Mr. Shoyad Ibn Sabur Khan Nuhash | G6: =IFERROR(INDEX('01_Theory Course List'!$H$2:$H$479,MATCH(C6,'01_Theory Course List'!$C$2:$C$479,0)),"") -> Mr. Md. Abdullah Al Mamun
B7: ='01_Theory Course List'!B7 -> 6 | C7: ='01_Theory Course List'!C7 -> BME 207 | D7: ='01_Theory Course List'!D7 -> Biomaterials | F7: =IFERROR(INDEX('01_Theory Course List'!$G$2:$G$479,MATCH(C7,'01_Theory Course List'!$C$2:$C$479,0)),"") -> Ms. Samina Nishat Binte Akram | G7: =IFERROR(INDEX('01_Theory Course List'!$H$2:$H$479,MATCH(C7,'01_Theory Course List'!$C$2:$C$479,0)),"") -> Dr. M. Tarik Arafat
B8: ='01_Theory Course List'!B8 -> 7 | C8: ='01_Theory Course List'!C8 -> BME 309 | D8: ='01_Theory Course List'!D8 -> Quantitative Physiology | F8: =IFERROR(INDEX('01_Theory Course List'!$G$2:$G$479,MATCH(C8,'01_Theory Course List'!$C$2:$C$479,0)),"") -> Mr. Md. Tazuddin Ahmed Akash | G8: =IFERROR(INDEX('01_Theory Course List'!$H$2:$H$479,MATCH(C8,'01_Theory Course List'!$C$2:$C$479,0)),"") -> Ms. Omi Bonik
B9: ='01_Theory Course List'!B9 -> 8 | C9: ='01_Theory Course List'!C9 -> BME 303 | D9: ='01_Theory Course List'!D9 -> Biomedical Instrumentation and Measurements | F9: =IFERROR(INDEX('01_Theory Course List'!$G$2:$G$479,MATCH(C9,'01_Theory Course List'!$C$2:$C$479,0)),"") -> Mr. Samiul Based Shuvo | G9: =IFERROR(INDEX('01_Theory Course List'!$H$2:$H$479,MATCH(C9,'01_Theory Course List'!$C$2:$C$479,0)),"") -> Mr. Sayeed Sajjad Razin
B10: ='01_Theory Course List'!B10 -> 9 | C10: ='01_Theory Course List'!C10 -> BME 311 | D10: ='01_Theory Course List'!D10 -> Biomedical Signals and Systems | F10: =IFERROR(INDEX('01_Theory Course List'!$G$2:$G$479,MATCH(C10,'01_Theory Course List'!$C$2:$C$479,0)),"") -> Mr. Shoyad Ibn Sabur Khan Nuhash | G10: =IFERROR(INDEX('01_Theory Course List'!$H$2:$H$479,MATCH(C10,'01_Theory Course List'!$C$2:$C$479,0)),"") -> Dr. Taufiq Hasan
B11: ='01_Theory Course List'!B11 -> 10 | C11: ='01_Theory Course List'!C11 -> BME 403 | D11: ='01_Theory Course List'!D11 -> Medical Imaging | F11: =IFERROR(INDEX('01_Theory Course List'!$G$2:$G$479,MATCH(C11,'01_Theory Course List'!$C$2:$C$479,0)),"") -> Ms. Tasnia Binte Mamun | G11: =IFERROR(INDEX('01_Theory Course List'!$H$2:$H$479,MATCH(C11,'01_Theory Course List'!$C$2:$C$479,0)),"") -> Mr. Shoyad Ibn Sabur Khan Nuhash
B12: ='01_Theory Course List'!B12 -> 11 | C12: ='01_Theory Course List'!C12 -> BME 409 (Elective) | D12: ='01_Theory Course List'!D12 -> Tissue Engineering and Regenerative Medicine | F12: =IFERROR(INDEX('01_Theory Course List'!$G$2:$G$479,MATCH(C12,'01_Theory Course List'!$C$2:$C$479,0)),"") -> Ms. Srija Sarker Anannya | G12: =IFERROR(INDEX('01_Theory Course List'!$H$2:$H$479,MATCH(C12,'01_Theory Course List'!$C$2:$C$479,0)),"") -> Ms. Chaity Chakraborty
B13: ='01_Theory Course List'!B13 -> 12 | C13: ='01_Theory Course List'!C13 -> BME 449 (Elective) | D13: ='01_Theory Course List'!D13 -> Machine Learning for Biomedical Engineers | F13: =IFERROR(INDEX('01_Theory Course List'!$G$2:$G$479,MATCH(C13,'01_Theory Course List'!$C$2:$C$479,0)),"") -> Dr. Taufiq Hasan | G13: =IFERROR(INDEX('01_Theory Course List'!$H$2:$H$479,MATCH(C13,'01_Theory Course List'!$C$2:$C$479,0)),"") -> Mr. Sayeed Sajjad Razin
B14: ='01_Theory Course List'!B14 -> 13 | C14: ='01_Theory Course List'!C14 -> BME 441 (Elective) | D14: ='01_Theory Course List'!D14 -> Neural Engineering | F14: =IFERROR(INDEX('01_Theory Course List'!$G$2:$G$479,MATCH(C14,'01_Theory Course List'!$C$2:$C$479,0)),"") -> Mr. Md. Tazuddin Ahmed Akash | G14: =IFERROR(INDEX('01_Theory Course List'!$H$2:$H$479,MATCH(C14,'01_Theory Course List'!$C$2:$C$479,0)),"") -> Mr. Samiul Based Shuvo
A15: Sessional | B15: 14 | C15: BME 202 | D15: Biomechanics Sessional | E15: A1 | F15: Mr. Md. Abdullah Al Mamun | G15: Ms. Srija Sarker Anannya | H15: Ms. Chaity Chakraborty
E16: A2 | F16: Mr. Md. Abdullah Al Mamun | G16: Ms. Srija Sarker Anannya | H16: Ms. Chaity Chakraborty
B17: 15 | C17: BME 204 | D17: Human Physiology Sessional | E17: A1 | F17: Mr. Shoyad Ibn Sabur Khan Nuhash | G17: Ms. Samina Nishat Binte Akram | H17: Ms. Tasnia Binte Mamun | I17: Ms. Chaity Chakraborty
E18: A2 | F18: Mr. Shoyad Ibn Sabur Khan Nuhash | G18: Ms. Samina Nishat Binte Akram | H18: Ms. Tasnia Binte Mamun | I18: Ms. Omi Bonik
B19: 16 | C19: BME 206 | D19: Biofluid Mechanics and Heat Transfer Sessional | E19: A1 | F19: Mr. Shoyad Ibn Sabur Khan Nuhash | G19: Mr. Md. Abdullah Al Mamun | H19: Ms. Omi Bonik
E20: A2 | F20: Mr. Shoyad Ibn Sabur Khan Nuhash | G20: Mr. Md. Abdullah Al Mamun | H20: Mr. Sadman Sakib Himel
B21: 17 | C21: BME 208 | D21: Biomaterials Sessional | E21: A1 | F21: Ms. Samina Nishat Binte Akram | G21: Ms. Srija Sarker Anannya | H21: Ms. Chaity Chakraborty
E22: A2 | F22: Ms. Samina Nishat Binte Akram | G22: Ms. Srija Sarker Anannya | H22: Ms. Chaity Chakraborty
B23: 18 | C23: BME 210 | D23: Numerial Techniques Sessional | E23: A1 | F23: Mr. Md. Tazuddin Ahmed Akash | G23: Mr. Sayeed Sajjad Razin | H23: Mr. Sadman Sakib Himel
E24: A2 | F24: Mr. Md. Tazuddin Ahmed Akash | G24: Mr. Sayeed Sajjad Razin | H24: Mr. Sadman Sakib Himel
B25: 19 | C25: BME 300 | D25: Biomedical Engineering Design - I | E25: A1 | F25: Mr. Shoyad Ibn Sabur Khan Nuhash | G25: Mr. Samiul Based Shuvo | H25: Mr. Md. Abdullah Al Mamun | I25: Ms. Samina Nishat Binte Akram | J25: Ms. Chaity Chakraborty
E26: A2 | F26: Mr. Samiul Based Shuvo | G26: Mr. Md. Tazuddin Ahmed Akash | H26: Mr. Md. Abdullah Al Mamun | I26: Ms. Srija Sarker Anannya | J26: Mr. Sayeed Sajjad Razin
B27: 20 | C27: BME 304 | D27: Biomedical Instrumentation and Measurements Sessional | E27: A1 | F27: Mr. Samiul Based Shuvo | G27: Mr. Sayeed Sajjad Razin | H27: Mr. Sadman Sakib Himel
E28: A2 | F28: Mr. Samiul Based Shuvo | G28: Mr. Sayeed Sajjad Razin | H28: Mr. Sadman Sakib Himel
B29: 21 | C29: BME 310 | D29: Communication Protocol for Biomedical Instruments Sessional | E29: A1 | F29: Mr. Md. Tazuddin Ahmed Akash | G29: Mr. Sayeed Sajjad Razin | H29: Mr. Sadman Sakib Himel
E30: A2 | F30: Ms. Tasnia Binte Mamun | G30: Ms. Omi Bonik | H30: Mr. Sadman Sakib Himel
B31: 22 | C31: BME 404 | D31: Medical Imaging Sessional | E31: A1 | F31: Mr. Md. Tazuddin Ahmed Akash | G31: Ms. Tasnia Binte Mamun | H31: Ms. Omi Bonik
E32: A2 | F32: Mr. Md. Tazuddin Ahmed Akash | G32: Ms. Tasnia Binte Mamun | H32: Ms. Omi Bonik
B33: 23 | C33: BME 400 | D33: Thesis | E33: X | F33: Dr. M. Tarik Arafat | G33: Dr. Taufiq Hasan | H33: Dr. Jahid Ferdous

Sheet 07_Sessional Grade Tracker
A1: ='02_Sessional Course List'!B1 -> SL No. | B1: ='02_Sessional Course List'!C1 -> Course Code | C1: ='02_Sessional Course List'!D1 -> Course Title | D1: ='02_Sessional Course List'!E1 -> Contact Hours | E1: ='02_Sessional Course List'!F1 -> Section | F1: Gradesheet Preparer | G1: Gradesheet Preparation Status | H1: Gradesheet Scrutinizer | I1: Gradesheet Scrutiny Status | J1: Final Gradesheet Submission to HOD Deadline | K1: Remarks/Notes
A2: ='02_Sessional Course List'!B2 -> 1 | B2: ='02_Sessional Course List'!C2 -> BME 202 | C2: ='02_Sessional Course List'!D2 -> Biomechanics Sessional | D2: ='02_Sessional Course List'!E2 -> 1.5 | E2: ='02_Sessional Course List'!F2 -> A1 | F2: Mr. Md. Abdullah Al Mamun | H2: Dr. Jahid Ferdous
E3: ='02_Sessional Course List'!F3 -> A2
A4: ='02_Sessional Course List'!B4 -> 2 | B4: ='02_Sessional Course List'!C4 -> BME 204 | C4: ='02_Sessional Course List'!D4 -> Human Physiology Sessional | D4: ='02_Sessional Course List'!E4 -> 3 | E4: ='02_Sessional Course List'!F4 -> A1 | F4: Ms. Tasnia Binte Mamun | H4: Dr. Jahid Ferdous
E5: ='02_Sessional Course List'!F5 -> A2
A6: ='02_Sessional Course List'!B6 -> 3 | B6: ='02_Sessional Course List'!C6 -> BME 206 | C6: ='02_Sessional Course List'!D6 -> Biofluid Mechanics and Heat Transfer Sessional | D6: ='02_Sessional Course List'!E6 -> 3 | E6: ='02_Sessional Course List'!F6 -> A1 | F6: Mr. Shoyad Ibn Sabur Khan Nuhash | H6: Dr. M. Tarik Arafat
E7: ='02_Sessional Course List'!F7 -> A2
A8: ='02_Sessional Course List'!B8 -> 4 | B8: ='02_Sessional Course List'!C8 -> BME 208 | C8: ='02_Sessional Course List'!D8 -> Biomaterials Sessional | D8: ='02_Sessional Course List'!E8 -> 3 | E8: ='02_Sessional Course List'!F8 -> A1 | F8: Ms. Samina Nishat Binte Akram | H8: Dr. M. Tarik Arafat
E9: ='02_Sessional Course List'!F9 -> A2
A10: ='02_Sessional Course List'!B10 -> 5 | B10: ='02_Sessional Course List'!C10 -> BME 210 | C10: ='02_Sessional Course List'!D10 -> Numerial Techniques Sessional | D10: ='02_Sessional Course List'!E10 -> 1.5 | E10: ='02_Sessional Course List'!F10 -> A1 | F10: Mr. Md. Tazuddin Ahmed Akash | H10: Dr. Jahid Ferdous
E11: ='02_Sessional Course List'!F11 -> A2
A12: ='02_Sessional Course List'!B12 -> 6 | B12: ='02_Sessional Course List'!C12 -> BME 300 | C12: ='02_Sessional Course List'!D12 -> Biomedical Engineering Design - I | D12: ='02_Sessional Course List'!E12 -> 3 | E12: ='02_Sessional Course List'!F12 -> A1 | F12: Mr. Samiul Based Shuvo | H12: Dr. Taufiq Hasan
E13: ='02_Sessional Course List'!F13 -> A2
A14: ='02_Sessional Course List'!B14 -> 7 | B14: ='02_Sessional Course List'!C14 -> BME 304 | C14: ='02_Sessional Course List'!D14 -> Biomedical Instrumentation and Measurements Sessional | D14: ='02_Sessional Course List'!E14 -> 3 | E14: ='02_Sessional Course List'!F14 -> A1 | F14: Mr. Sayeed Sajjad Razin | H14: Dr. Taufiq Hasan
E15: ='02_Sessional Course List'!F15 -> A2
A16: ='02_Sessional Course List'!B16 -> 8 | B16: ='02_Sessional Course List'!C16 -> BME 310 | C16: ='02_Sessional Course List'!D16 -> Communication Protocol for Biomedical Instruments Sessional | D16: ='02_Sessional Course List'!E16 -> 3 | E16: ='02_Sessional Course List'!F16 -> A1 | F16: Mr. Sadman Sakib Himel | H16: Dr. Taufiq Hasan
E17: ='02_Sessional Course List'!F17 -> A2
A18: ='02_Sessional Course List'!B18 -> 9 | B18: ='02_Sessional Course List'!C18 -> BME 404 | C18: ='02_Sessional Course List'!D18 -> Medical Imaging Sessional | D18: ='02_Sessional Course List'!E18 -> 3 | E18: ='02_Sessional Course List'!F18 -> A1 | F18: Ms. Omi Bonik | H18: Mr. Shoyad Ibn Sabur Khan Nuhash
E19: ='02_Sessional Course List'!F19 -> A2
A20: ='02_Sessional Course List'!B20 -> 10 | B20: ='02_Sessional Course List'!C20 -> BME 400 | C20: ='02_Sessional Course List'!D20 -> Thesis | D20: ='02_Sessional Course List'!E20 -> 6 | E20: ='02_Sessional Course List'!F20 -> X | F20: Dr. M. Tarik Arafat | H20: Dr. Jahid Ferdous

Sheet 08_Theory Grade Tracker
B1: Course Info | D1: Question Preparation | I1: Question Moderation | M1: Script Examination | Q1: Script Scrutiny | S1: Gradesheet Preparation | U1: Gradesheet Scrutiny | W1: Final Gradesheet Submission to HOD Deadline | X1: Remarks/Notes
A2: ='01_Theory Course List'!B1 -> SL No. | B2: ='01_Theory Course List'!C1 -> Course Code | C2: ='01_Theory Course List'!D1 -> Course Title | D2: Question Preparer (Sec A) | E2: Question Preparation (Sec A) Status | F2: Question Preparer (Sec B) | G2: Question Preparation (Sec B) Status | H2: Question Submission Deadline | I2: Question Moderator 01 | J2: QM 01 Status | K2: Question Moderator 02 | L2: QM 02 Status | M2: Examiner (Sec A) | N2: Examination (Sec A) Status | O2: Examiner (Sec B) | P2: Examination (Sec B) Status | Q2: Script Scrutinizer | R2: Script Scrutiny Status | S2: Gradesheet Preparer | T2: Gradesheet Preparation Status | U2: Gradesheet Scrutinizer | V2: Gradesheet Scrutiny Status
A3: ='01_Theory Course List'!B2 -> 1 | B3: ='01_Theory Course List'!C2 -> BME 101 | C3: ='01_Theory Course List'!D2 -> Introduction to Biomedical Engineering | D3: Dr. M. Tarik Arafat | F3: Dr. Jahid Ferdous | I3: Dr. Taufiq Hasan | K3: Mr. Shoyad Ibn Sabur Khan Nuhash | M3: =D3 -> Dr. M. Tarik Arafat | O3: =F3 -> Dr. Jahid Ferdous | Q3: Mr. Shoyad Ibn Sabur Khan Nuhash | S3: Dr. M. Tarik Arafat | U3: Mr. Shoyad Ibn Sabur Khan Nuhash
A4: ='01_Theory Course List'!B3 -> 2 | B4: ='01_Theory Course List'!C3 -> BME 201 | C4: ='01_Theory Course List'!D3 -> Biomechanics | D4: Mr. Md. Abdullah Al Mamun | F4: Ms. Srija Sarker Anannya | I4: Dr. M. Tarik Arafat | K4: Dr. Jahid Ferdous | M4: =D4 -> Mr. Md. Abdullah Al Mamun | O4: =F4 -> Ms. Srija Sarker Anannya | Q4: Mr. Sadman Sakib Himel | S4: Mr. Md. Abdullah Al Mamun | U4: Mr. Sadman Sakib Himel
A5: ='01_Theory Course List'!B4 -> 3 | B5: ='01_Theory Course List'!C4 -> BME 203 | C5: ='01_Theory Course List'!D4 -> Human Physiology | D5: Ms. Tasnia Binte Mamun | F5: Ms. Chaity Chakraborty | I5: Dr. Jahid Ferdous | K5: Mr. Samiul Based Shuvo | M5: =D5 -> Ms. Tasnia Binte Mamun | O5: =F5 -> Ms. Chaity Chakraborty | Q5: Mr. Md. Tazuddin Ahmed Akash | S5: Ms. Tasnia Binte Mamun | U5: Mr. Md. Tazuddin Ahmed Akash
A6: ='01_Theory Course List'!B5 -> 4 | B6: ='01_Theory Course List'!C5 -> BME 211 | C6: ='01_Theory Course List'!D5 -> Bioelectricity | D6: Mr. Samiul Based Shuvo | F6: Mr. Sadman Sakib Himel | I6: Dr. M. Tarik Arafat | K6: Mr. Shoyad Ibn Sabur Khan Nuhash | M6: =D6 -> Mr. Samiul Based Shuvo | O6: =F6 -> Mr. Sadman Sakib Himel | Q6: Mr. Md. Abdullah Al Mamun | S6: Mr. Samiul Based Shuvo | U6: Mr. Md. Abdullah Al Mamun
A7: ='01_Theory Course List'!B6 -> 5 | B7: ='01_Theory Course List'!C6 -> BME 205 | C7: ='01_Theory Course List'!D6 -> Biofluid Mechanics and Heat Transfer | D7: Mr. Shoyad Ibn Sabur Khan Nuhash | F7: Mr. Md. Abdullah Al Mamun | I7: Dr. M. Tarik Arafat | K7: Dr. Jahid Ferdous | M7: =D7 -> Mr. Shoyad Ibn Sabur Khan Nuhash | O7: =F7 -> Mr. Md. Abdullah Al Mamun | Q7: Ms. Tasnia Binte Mamun | S7: Mr. Shoyad Ibn Sabur Khan Nuhash | U7: Ms. Tasnia Binte Mamun
A8: ='01_Theory Course List'!B7 -> 6 | B8: ='01_Theory Course List'!C7 -> BME 207 | C8: ='01_Theory Course List'!D7 -> Biomaterials | D8: Ms. Samina Nishat Binte Akram | F8: Dr. M. Tarik Arafat | I8: Dr. Jahid Ferdous | K8: Mr. Samiul Based Shuvo | M8: =D8 -> Ms. Samina Nishat Binte Akram | O8: =F8 -> Dr. M. Tarik Arafat | Q8: Ms. Srija Sarker Anannya | S8: Ms. Samina Nishat Binte Akram | U8: Ms. Srija Sarker Anannya
A9: ='01_Theory Course List'!B8 -> 7 | B9: ='01_Theory Course List'!C8 -> BME 309 | C9: ='01_Theory Course List'!D8 -> Quantitative Physiology | D9: Mr. Md. Tazuddin Ahmed Akash | F9: Ms. Omi Bonik | I9: Dr. Jahid Ferdous | K9: Mr. Shoyad Ibn Sabur Khan Nuhash | M9: =D9 -> Mr. Md. Tazuddin Ahmed Akash | O9: =F9 -> Ms. Omi Bonik | Q9: Mr. Sayeed Sajjad Razin | S9: Mr. Md. Tazuddin Ahmed Akash | U9: Mr. Sayeed Sajjad Razin
A10: ='01_Theory Course List'!B9 -> 8 | B10: ='01_Theory Course List'!C9 -> BME 303 | C10: ='01_Theory Course List'!D9 -> Biomedical Instrumentation and Measurements | D10: Mr. Sayeed Sajjad Razin | F10: Mr. Samiul Based Shuvo | I10: Dr. Taufiq Hasan | K10: Mr. Shoyad Ibn Sabur Khan Nuhash | M10: =D10 -> Mr. Sayeed Sajjad Razin | O10: =F10 -> Mr. Samiul Based Shuvo | Q10: Ms. Samina Nishat Binte Akram | S10: Mr. Sayeed Sajjad Razin | U10: Ms. Samina Nishat Binte Akram
A11: ='01_Theory Course List'!B10 -> 9 | B11: ='01_Theory Course List'!C10 -> BME 311 | C11: ='01_Theory Course List'!D10 -> Biomedical Signals and Systems | D11: Mr. Shoyad Ibn Sabur Khan Nuhash | F11: Dr. Taufiq Hasan | I11: Mr. Samiul Based Shuvo | K11: Dr. M. Tarik Arafat | M11: =D11 -> Mr. Shoyad Ibn Sabur Khan Nuhash | O11: =F11 -> Dr. Taufiq Hasan | Q11: Ms. Chaity Chakraborty | S11: Mr. Shoyad Ibn Sabur Khan Nuhash | U11: Ms. Chaity Chakraborty
A12: ='01_Theory Course List'!B11 -> 10 | B12: ='01_Theory Course List'!C11 -> BME 403 | C12: ='01_Theory Course List'!D11 -> Medical Imaging | D12: Ms. Tasnia Binte Mamun | F12: Mr. Shoyad Ibn Sabur Khan Nuhash | I12: Dr. Taufiq Hasan | K12: Mr. Samiul Based Shuvo | M12: =D12 -> Ms. Tasnia Binte Mamun | O12: =F12 -> Mr. Shoyad Ibn Sabur Khan Nuhash | Q12: Ms. Omi Bonik | S12: Ms. Tasnia Binte Mamun | U12: Ms. Omi Bonik
A13: ='01_Theory Course List'!B12 -> 11 | B13: ='01_Theory Course List'!C12 -> BME 409 (Elective) | C13: ='01_Theory Course List'!D12 -> Tissue Engineering and Regenerative Medicine | D13: Ms. Srija Sarker Anannya | F13: Ms. Chaity Chakraborty | I13: Dr. M. Tarik Arafat | K13: Dr. Jahid Ferdous | M13: =D13 -> Ms. Srija Sarker Anannya | O13: =F13 -> Ms. Chaity Chakraborty | Q13: Mr. Samiul Based Shuvo | S13: Ms. Srija Sarker Anannya | U13: Mr. Samiul Based Shuvo
A14: ='01_Theory Course List'!B13 -> 12 | B14: ='01_Theory Course List'!C13 -> BME 449 (Elective) | C14: ='01_Theory Course List'!D13 -> Machine Learning for Biomedical Engineers | D14: Dr. Taufiq Hasan | F14: Mr. Sayeed Sajjad Razin | I14: Mr. Samiul Based Shuvo | K14: Mr. Shoyad Ibn Sabur Khan Nuhash | M14: =D14 -> Dr. Taufiq Hasan | O14: =F14 -> Mr. Sayeed Sajjad Razin | Q14: Mr. Shoyad Ibn Sabur Khan Nuhash | S14: Dr. Taufiq Hasan | U14: Mr. Shoyad Ibn Sabur Khan Nuhash
A15: ='01_Theory Course List'!B14 -> 13 | B15: ='01_Theory Course List'!C14 -> BME 441 (Elective) | C15: ='01_Theory Course List'!D14 -> Neural Engineering | D15: Mr. Md. Tazuddin Ahmed Akash | F15: Mr. Samiul Based Shuvo | I15: Dr. Taufiq Hasan | K15: Mr. Shoyad Ibn Sabur Khan Nuhash | M15: =D15 -> Mr. Md. Tazuddin Ahmed Akash | O15: =F15 -> Mr. Samiul Based Shuvo | Q15: Mr. Md. Abdullah Al Mamun | S15: Mr. Md. Tazuddin Ahmed Akash | U15: Mr. Md. Abdullah Al Mamun
A16: =IF('01_Theory Course List'!B15 = "", "", '01_Theory Course List'!B15) | B16: =IF('01_Theory Course List'!C15 = "", "", '01_Theory Course List'!C15) | C16: =IFERROR(INDEX('01_Theory Course List'!$D$2:$D$479,MATCH(B16,'01_Theory Course List'!$C$2:$C$479,0)),"")
A17: =IF('01_Theory Course List'!B16 = "", "", '01_Theory Course List'!B16) | B17: =IF('01_Theory Course List'!C16 = "", "", '01_Theory Course List'!C16) | C17: =IFERROR(INDEX('01_Theory Course List'!$D$2:$D$479,MATCH(B17,'01_Theory Course List'!$C$2:$C$479,0)),"")
A18: =IF('01_Theory Course List'!B17 = "", "", '01_Theory Course List'!B17) | B18: =IF('01_Theory Course List'!C17 = "", "", '01_Theory Course List'!C17) | C18: =IFERROR(INDEX('01_Theory Course List'!$D$2:$D$479,MATCH(B18,'01_Theory Course List'!$C$2:$C$479,0)),"")
A19: =IF('01_Theory Course List'!B18 = "", "", '01_Theory Course List'!B18) | B19: =IF('01_Theory Course List'!C18 = "", "", '01_Theory Course List'!C18) | C19: =IFERROR(INDEX('01_Theory Course List'!$D$2:$D$479,MATCH(B19,'01_Theory Course List'!$C$2:$C$479,0)),"")
A20: =IF('01_Theory Course List'!B19 = "", "", '01_Theory Course List'!B19) | B20: =IF('01_Theory Course List'!C19 = "", "", '01_Theory Course List'!C19) | C20: =IFERROR(INDEX('01_Theory Course List'!$D$2:$D$479,MATCH(B20,'01_Theory Course List'!$C$2:$C$479,0)),"")
B21: =IF('01_Theory Course List'!C20 = "", "", '01_Theory Course List'!C20) | C21: =IFERROR(INDEX('01_Theory Course List'!$D$2:$D$479,MATCH(B21,'01_Theory Course List'!$C$2:$C$479,0)),"")
B22: =IF('01_Theory Course List'!C21 = "", "", '01_Theory Course List'!C21) | C22: =IFERROR(INDEX('01_Theory Course List'!$D$2:$D$479,MATCH(B22,'01_Theory Course List'!$C$2:$C$479,0)),"")
C23: =IFERROR(INDEX('01_Theory Course List'!$D$2:$D$479,MATCH(B23,'01_Theory Course List'!$C$2:$C$479,0)),"")
C24: =IFERROR(INDEX('01_Theory Course List'!$D$2:$D$479,MATCH(B24,'01_Theory Course List'!$C$2:$C$479,0)),"")
C25: =IFERROR(INDEX('01_Theory Course List'!$D$2:$D$479,MATCH(B25,'01_Theory Course List'!$C$2:$C$479,0)),"")
C26: =IFERROR(INDEX('01_Theory Course List'!$D$2:$D$479,MATCH(B26,'01_Theory Course List'!$C$2:$C$479,0)),"")
C27: =IFERROR(INDEX('01_Theory Course List'!$D$2:$D$479,MATCH(B27,'01_Theory Course List'!$C$2:$C$479,0)),"")
C28: =IFERROR(INDEX('01_Theory Course List'!$D$2:$D$479,MATCH(B28,'01_Theory Course List'!$C$2:$C$479,0)),"")
C29: =IFERROR(INDEX('01_Theory Course List'!$D$2:$D$479,MATCH(B29,'01_Theory Course List'!$C$2:$C$479,0)),"")
C30: =IFERROR(INDEX('01_Theory Course List'!$D$2:$D$479,MATCH(B30,'01_Theory Course List'!$C$2:$C$479,0)),"")
C31: =IFERROR(INDEX('01_Theory Course List'!$D$2:$D$479,MATCH(B31,'01_Theory Course List'!$C$2:$C$479,0)),"")
C32: =IFERROR(INDEX('01_Theory Course List'!$D$2:$D$479,MATCH(B32,'01_Theory Course List'!$C$2:$C$479,0)),"")
C33: =IFERROR(INDEX('01_Theory Course List'!$D$2:$D$479,MATCH(B33,'01_Theory Course List'!$C$2:$C$479,0)),"")
C34: =IFERROR(INDEX('01_Theory Course List'!$D$2:$D$479,MATCH(B34,'01_Theory Course List'!$C$2:$C$479,0)),"")
... C62: =IFERROR(INDEX('01_Theory Course List'!$D$2:$D$479,MATCH(B62,'01_Theory Course List'!$C$2:$C$479,0)),"")

Sheet 09_CF_CAR Tracker
A1: Type of Course | B1: ='01_Theory Course List'!B1 -> SL No. | C1: ='01_Theory Course List'!C1 -> Course Code | D1: ='01_Theory Course List'!D1 -> Course Title | E1: Section | F1: Course Teacher 01 | G1: Course Teacher 02 | H1: Course Teacher 03 | I1: Course Teacher 04 | J1: Course Teacher 05 | K1: CAR/Course File Preparation Status | L1: CAR/Course File Preparation Deadline | M1: Remarks/Notes
A2: Theory | B2: ='01_Theory Course List'!B2 -> 1 | C2: ='01_Theory Course List'!C2 -> BME 101 | D2: ='01_Theory Course List'!D2 -> Introduction to Biomedical Engineering | E2: X | F2: =IFERROR(INDEX('01_Theory Course List'!$G$2:$G$479,MATCH(C2,'01_Theory Course List'!$C$2:$C$479,0)),"") -> Dr. M. Tarik Arafat | G2: =IFERROR(INDEX('01_Theory Course List'!$H$2:$H$479,MATCH(C2,'01_Theory Course List'!$C$2:$C$479,0)),"") -> Dr. Jahid Ferdous | L2: 46326
B3: ='01_Theory Course List'!B3 -> 2 | C3: ='01_Theory Course List'!C3 -> BME 201 | D3: ='01_Theory Course List'!D3 -> Biomechanics | F3: =IFERROR(INDEX('01_Theory Course List'!$G$2:$G$479,MATCH(C3,'01_Theory Course List'!$C$2:$C$479,0)),"") -> Mr. Md. Abdullah Al Mamun | G3: =IFERROR(INDEX('01_Theory Course List'!$H$2:$H$479,MATCH(C3,'01_Theory Course List'!$C$2:$C$479,0)),"") -> Ms. Srija Sarker Anannya
B4: ='01_Theory Course List'!B4 -> 3 | C4: ='01_Theory Course List'!C4 -> BME 203 | D4: ='01_Theory Course List'!D4 -> Human Physiology | F4: =IFERROR(INDEX('01_Theory Course List'!$G$2:$G$479,MATCH(C4,'01_Theory Course List'!$C$2:$C$479,0)),"") -> Ms. Tasnia Binte Mamun | G4: =IFERROR(INDEX('01_Theory Course List'!$H$2:$H$479,MATCH(C4,'01_Theory Course List'!$C$2:$C$479,0)),"") -> Ms. Chaity Chakraborty
B5: ='01_Theory Course List'!B5 -> 4 | C5: ='01_Theory Course List'!C5 -> BME 211 | D5: ='01_Theory Course List'!D5 -> Bioelectricity | F5: =IFERROR(INDEX('01_Theory Course List'!$G$2:$G$479,MATCH(C5,'01_Theory Course List'!$C$2:$C$479,0)),"") -> Mr. Samiul Based Shuvo | G5: =IFERROR(INDEX('01_Theory Course List'!$H$2:$H$479,MATCH(C5,'01_Theory Course List'!$C$2:$C$479,0)),"") -> Mr. Sadman Sakib Himel
B6: ='01_Theory Course List'!B6 -> 5 | C6: ='01_Theory Course List'!C6 -> BME 205 | D6: ='01_Theory Course List'!D6 -> Biofluid Mechanics and Heat Transfer | F6: =IFERROR(INDEX('01_Theory Course List'!$G$2:$G$479,MATCH(C6,'01_Theory Course List'!$C$2:$C$479,0)),"") -> Mr. Shoyad Ibn Sabur Khan Nuhash | G6: =IFERROR(INDEX('01_Theory Course List'!$H$2:$H$479,MATCH(C6,'01_Theory Course List'!$C$2:$C$479,0)),"") -> Mr. Md. Abdullah Al Mamun
B7: ='01_Theory Course List'!B7 -> 6 | C7: ='01_Theory Course List'!C7 -> BME 207 | D7: ='01_Theory Course List'!D7 -> Biomaterials | F7: =IFERROR(INDEX('01_Theory Course List'!$G$2:$G$479,MATCH(C7,'01_Theory Course List'!$C$2:$C$479,0)),"") -> Ms. Samina Nishat Binte Akram | G7: =IFERROR(INDEX('01_Theory Course List'!$H$2:$H$479,MATCH(C7,'01_Theory Course List'!$C$2:$C$479,0)),"") -> Dr. M. Tarik Arafat
B8: ='01_Theory Course List'!B8 -> 7 | C8: ='01_Theory Course List'!C8 -> BME 309 | D8: ='01_Theory Course List'!D8 -> Quantitative Physiology | F8: =IFERROR(INDEX('01_Theory Course List'!$G$2:$G$479,MATCH(C8,'01_Theory Course List'!$C$2:$C$479,0)),"") -> Mr. Md. Tazuddin Ahmed Akash | G8: =IFERROR(INDEX('01_Theory Course List'!$H$2:$H$479,MATCH(C8,'01_Theory Course List'!$C$2:$C$479,0)),"") -> Ms. Omi Bonik
B9: ='01_Theory Course List'!B9 -> 8 | C9: ='01_Theory Course List'!C9 -> BME 303 | D9: ='01_Theory Course List'!D9 -> Biomedical Instrumentation and Measurements | F9: =IFERROR(INDEX('01_Theory Course List'!$G$2:$G$479,MATCH(C9,'01_Theory Course List'!$C$2:$C$479,0)),"") -> Mr. Samiul Based Shuvo | G9: =IFERROR(INDEX('01_Theory Course List'!$H$2:$H$479,MATCH(C9,'01_Theory Course List'!$C$2:$C$479,0)),"") -> Mr. Sayeed Sajjad Razin
B10: ='01_Theory Course List'!B10 -> 9 | C10: ='01_Theory Course List'!C10 -> BME 311 | D10: ='01_Theory Course List'!D10 -> Biomedical Signals and Systems | F10: =IFERROR(INDEX('01_Theory Course List'!$G$2:$G$479,MATCH(C10,'01_Theory Course List'!$C$2:$C$479,0)),"") -> Mr. Shoyad Ibn Sabur Khan Nuhash | G10: =IFERROR(INDEX('01_Theory Course List'!$H$2:$H$479,MATCH(C10,'01_Theory Course List'!$C$2:$C$479,0)),"") -> Dr. Taufiq Hasan
B11: ='01_Theory Course List'!B11 -> 10 | C11: ='01_Theory Course List'!C11 -> BME 403 | D11: ='01_Theory Course List'!D11 -> Medical Imaging | F11: =IFERROR(INDEX('01_Theory Course List'!$G$2:$G$479,MATCH(C11,'01_Theory Course List'!$C$2:$C$479,0)),"") -> Ms. Tasnia Binte Mamun | G11: =IFERROR(INDEX('01_Theory Course List'!$H$2:$H$479,MATCH(C11,'01_Theory Course List'!$C$2:$C$479,0)),"") -> Mr. Shoyad Ibn Sabur Khan Nuhash
B12: ='01_Theory Course List'!B12 -> 11 | C12: ='01_Theory Course List'!C12 -> BME 409 (Elective) | D12: ='01_Theory Course List'!D12 -> Tissue Engineering and Regenerative Medicine | F12: =IFERROR(INDEX('01_Theory Course List'!$G$2:$G$479,MATCH(C12,'01_Theory Course List'!$C$2:$C$479,0)),"") -> Ms. Srija Sarker Anannya | G12: =IFERROR(INDEX('01_Theory Course List'!$H$2:$H$479,MATCH(C12,'01_Theory Course List'!$C$2:$C$479,0)),"") -> Ms. Chaity Chakraborty
B13: ='01_Theory Course List'!B13 -> 12 | C13: ='01_Theory Course List'!C13 -> BME 449 (Elective) | D13: ='01_Theory Course List'!D13 -> Machine Learning for Biomedical Engineers | F13: =IFERROR(INDEX('01_Theory Course List'!$G$2:$G$479,MATCH(C13,'01_Theory Course List'!$C$2:$C$479,0)),"") -> Dr. Taufiq Hasan | G13: =IFERROR(INDEX('01_Theory Course List'!$H$2:$H$479,MATCH(C13,'01_Theory Course List'!$C$2:$C$479,0)),"") -> Mr. Sayeed Sajjad Razin
B14: ='01_Theory Course List'!B14 -> 13 | C14: ='01_Theory Course List'!C14 -> BME 441 (Elective) | D14: ='01_Theory Course List'!D14 -> Neural Engineering | F14: =IFERROR(INDEX('01_Theory Course List'!$G$2:$G$479,MATCH(C14,'01_Theory Course List'!$C$2:$C$479,0)),"") -> Mr. Md. Tazuddin Ahmed Akash | G14: =IFERROR(INDEX('01_Theory Course List'!$H$2:$H$479,MATCH(C14,'01_Theory Course List'!$C$2:$C$479,0)),"") -> Mr. Samiul Based Shuvo
A15: Sessional | B15: 14 | C15: BME 202 | D15: Biomechanics Sessional | E15: A1 | F15: Mr. Md. Abdullah Al Mamun | G15: Ms. Srija Sarker Anannya | H15: Ms. Chaity Chakraborty
E16: A2 | F16: Mr. Md. Abdullah Al Mamun | G16: Ms. Srija Sarker Anannya | H16: Ms. Chaity Chakraborty
B17: 15 | C17: BME 204 | D17: Human Physiology Sessional | E17: A1 | F17: Mr. Shoyad Ibn Sabur Khan Nuhash | G17: Ms. Samina Nishat Binte Akram | H17: Ms. Tasnia Binte Mamun | I17: Ms. Chaity Chakraborty
E18: A2 | F18: Mr. Shoyad Ibn Sabur Khan Nuhash | G18: Ms. Samina Nishat Binte Akram | H18: Ms. Tasnia Binte Mamun | I18: Ms. Omi Bonik
B19: 16 | C19: BME 206 | D19: Biofluid Mechanics and Heat Transfer Sessional | E19: A1 | F19: Mr. Shoyad Ibn Sabur Khan Nuhash | G19: Mr. Md. Abdullah Al Mamun | H19: Ms. Omi Bonik
E20: A2 | F20: Mr. Shoyad Ibn Sabur Khan Nuhash | G20: Mr. Md. Abdullah Al Mamun | H20: Mr. Sadman Sakib Himel
B21: 17 | C21: BME 208 | D21: Biomaterials Sessional | E21: A1 | F21: Ms. Samina Nishat Binte Akram | G21: Ms. Srija Sarker Anannya | H21: Ms. Chaity Chakraborty
E22: A2 | F22: Ms. Samina Nishat Binte Akram | G22: Ms. Srija Sarker Anannya | H22: Ms. Chaity Chakraborty
